Workbook

Sheet 1. Méthodologie
A1: CARTOGRAPHIE DES RISQUES DE CORRUPTION
A2: LOI SAPIN 2, ARTICLE 17
A4: Entité concernée | B4: ABC4
A5: Version du document | B5: V1.0
A6: Date d'établissement | B6: 46119
A7: Établi par | B7: [Nom, Fonction]
A8: Validé par (Responsable conformité) | B8: [Nom, Date]
A9: Approuvé par (Direction générale) | B9: [Nom, Date]
A12: OBJECTIF DE LA CARTOGRAPHIE
A13: La cartographie des risques de corruption constitue le socle du dispositif anticorruption (recommandations AFA §118-§170). Elle vise à identifier, évaluer, hiérarchiser et gérer les risques de corruption auxquels l'entreprise est exposée dans le cadre de ses activités et de ses interactions avec les tiers.
A16: PÉRIMÈTRE DES INFRACTIONS COUVERTES
A17: Infraction | B17: Base légale
A18: Corruption active et passive | B18: Articles 433-1, 435-3 du Code pénal
A19: Trafic d'influence | B19: Articles 433-1, 433-2 du Code pénal
A20: Concussion | B20: Article 432-10 du Code pénal
A21: Prise illégale d'intérêts | B21: Article 432-12 du Code pénal
A22: Détournement de fonds publics | B22: Article 432-15 du Code pénal
A23: Favoritisme | B23: Article 432-14 du Code pénal
A25: MÉTHODE DE COTATION : MATRICE 4×4
A27: Échelle de PROBABILITÉ (occurrence)
A28: 1 : Rare | B28: Aucun antécédent, contrôles forts, faible exposition au processus
A29: 2 : Peu probable | B29: Quelques situations favorables mais environnement globalement maîtrisé
A30: 3 : Probable | B30: Conditions réunies : secteur exposé, zone à risque, processus peu encadré
A31: 4 : Très probable | B31: Antécédents connus, exposition forte, contrôles faibles ou absents
A33: Échelle d'IMPACT (gravité)
A34: 1 : Mineur | B34: Impact financier limité, pas de conséquence judiciaire directe
A35: 2 : Modéré | B35: Impact financier significatif, risque d'image local, procédure interne
A36: 3 : Majeur | B36: Poursuites pénales possibles, impact réputationnel fort, perte de marchés
A37: 4 : Critique | B37: Sanctions pénales, exclusion marchés publics, CJIP, mise en cause des dirigeants
A40: MATRICE DE COTATION (Score = Probabilité × Impact)
A42: Probabilité \ Impact | B42: Impact 1 Mineur | C42: Impact 2 Modéré | D42: Impact 3 Majeur | E42: Impact 4 Critique
A43: 4 : Très probable | B43: 4 | C43: 8 | D43: 12 | E43: 16
A44: 3 : Probable | B44: 3 | C44: 6 | D44: 9 | E44: 12
A45: 2 : Peu probable | B45: 2 | C45: 4 | D45: 6 | E45: 8
A46: 1 : Rare | B46: 1 | C46: 2 | D46: 3 | E46: 4
A48: SEUILS DE DÉCISION
B49: 1-3 : Faible | C49: Mesures de base suffisantes. Surveillance dans le cadre du contrôle interne courant. Revue lors de la mise à jour annuelle de la cartographie.
B50: 4-6 : Modéré | C50: Mesures de prévention existantes à formaliser ou renforcer. Suivi régulier par le responsable de processus. Inclusion dans le plan de contrôle interne.
B51: 8-9 : Élevé | C51: Plan d'action correctif dédié avec pilote et échéance. Validation par le responsable conformité. Formation ciblée des équipes exposées. Contrôle renforcé.
B52: 12-16 : Critique | C52: Traitement immédiat. Escalade à la direction générale et au comité d'éthique/conformité. Audit dédié. Mesures conservatoires si nécessaire (suspension de processus, gel de relation tiers).
...

Sheet All
A1: CARTOGRAPHIE DES RISQUES : PROCESSUS ACHATS & APPROVISIONNEMENT
A2: 💡 Les scénarios ci-dessous sont des EXEMPLES. Adaptez-les à votre entreprise, ajoutez vos propres scénarios et supprimez ceux non pertinents.
A4: N° | B4: Processus | C4: Scénario de corruption | D4: Description du risque | E4: Facteurs aggravants | F4: Probabilité (1-4) | G4: Impact (1-4) | H4: Score brut | I4: Niveau brut | J4: Mesures de prévention existantes | K4: Probabilité réelle (1-4) | L4: Impact réel (1-4) | M4: Score réel | N4: Niveau réel | O4: Actions correctives / Gap
A5: A1 | B5: Achats & Approvisionnement | C5: Pot-de-vin fournisseur | D5: Un acheteur favorise un fournisseur en échange d'une rétrocommission ou d'un avantage personnel (voyage, cadeau, emploi d'un proche). | E5: Fournisseur unique / pas de mise en concurrence, montant élevé, zone géographique à risque | F5: 4 | G5: 3 | H5: =IF(AND(F5<>"",G5<>""),F5*G5,"") -> 12 | I5: =IF(H5="","",IF(H5>=12,"🔴 Critique",IF(H5>=8,"🟠 Élevé",IF(H5>=4,"🟡 Modéré","🟢 Faible")))) -> 🔴 Critique | J5: • Procédure achats avec mise en concurrence• Séparation des rôles demandeur / acheteur / valideur• Politique cadeaux & invitations• Code de conduite anticorruption | K5: 3 | L5: 3 | M5: =IF(AND(K5<>"",L5<>""),K5*L5,"") -> 9 | N5: =IF(M5="","",IF(M5>=12,"🔴 Critique",IF(M5>=8,"🟠 Élevé",IF(M5>=4,"🟡 Modéré","🟢 Faible")))) -> 🟠 Élevé
A6: A2 | B6: Achats & Approvisionnement | C6: Surfacturation complice | D6: Un fournisseur surfacture une prestation avec l'accord d'un collaborateur interne qui valide la facture ; l'écart est partagé. | E6: Prestation intellectuelle (difficile à vérifier), absence de bon de commande préalable | F6: 1 | G6: 2 | H6: =IF(AND(F6<>"",G6<>""),F6*G6,"") -> 2 | I6: =IF(H6="","",IF(H6>=12,"🔴 Critique",IF(H6>=8,"🟠 Élevé",IF(H6>=4,"🟡 Modéré","🟢 Faible")))) -> 🟢 Faible | J6: • Bon de commande ou contrat préalable• Validation hiérarchique des factures• Rapprochement facture / prestation par la finance• Contrôles internes ponctuels | K6: 3 | L6: 3 | M6: =IF(AND(K6<>"",L6<>""),K6*L6,"") -> 9 | N6: =IF(M6="","",IF(M6>=12,"🔴 Critique",IF(M6>=8,"🟠 Élevé",IF(M6>=4,"🟡 Modéré","🟢 Faible")))) -> 🟠 Élevé
A7: A3 | B7: Achats & Approvisionnement | C7: Fractionnement de commandes | D7: Un acheteur fractionne volontairement des commandes pour rester sous les seuils d'approbation et éviter les contrôles. | E7: Seuils de validation élevés, pas de contrôle de cumul par fournisseur | F7: 3 | G7: 2 | H7: =IF(AND(F7<>"",G7<>""),F7*G7,"") -> 6 | I7: =IF(H7="","",IF(H7>=12,"🔴 Critique",IF(H7>=8,"🟠 Élevé",IF(H7>=4,"🟡 Modéré","🟢 Faible")))) -> 🟡 Modéré | J7: Seuils d’approbation formalisés dans la procédure achats Validation hiérarchique obligatoire pour toute commande Supervision a posteriori des volumes d’achats par fournisseur Sensibilisation des acheteurs aux règles de contournement des seuils | K7: 3 | L7: 2 | M7: =IF(AND(K7<>"",L7<>""),K7*L7,"") -> 6 | N7: =IF(M7="","",IF(M7>=12,"🔴 Critique",IF(M7>=8,"🟠 Élevé",IF(M7>=4,"🟡 Modéré","🟢 Faible")))) -> 🟡 Modéré
A8: A4 | B8: Achats & Approvisionnement | C8: Conflit d'intérêts achats | D8: Un collaborateur en charge des achats a un lien familial, amical ou financier avec un fournisseur sans le déclarer. | E8: Absence de registre des conflits d'intérêts, secteur à forte sous-traitance | F8: 2 | G8: 3 | H8: =IF(AND(F8<>"",G8<>""),F8*G8,"") -> 6 | I8: =IF(H8="","",IF(H8>=12,"🔴 Critique",IF(H8>=8,"🟠 Élevé",IF(H8>=4,"🟡 Modéré","🟢 Faible")))) -> 🟡 Modéré | J8: Code de conduite rappelant l’obligation de prévenir les conflits d’intérêts Engagement déontologique signé par les collaborateurs achats Possibilité de signalement via un dispositif d’alerte interne Contrôle ponctuel des fournisseurs sensibles par la conformité | K8: 3 | L8: 2 | M8: =IF(AND(K8<>"",L8<>""),K8*L8,"") -> 6 | N8: =IF(M8="","",IF(M8>=12,"🔴 Critique",IF(M8>=8,"🟠 Élevé",IF(M8>=4,"🟡 Modéré","🟢 Faible")))) -> 🟡 Modéré
A9: A5 | B9: Achats & Approvisionnement | C9: Faux fournisseur / société écran | D9: Création d'un fournisseur fictif par un collaborateur interne pour détourner des fonds via de fausses factures. | E9: Processus de référencement fournisseur faible, contrôles comptables insuffisants | F9: 1 | G9: 3 | H9: =IF(AND(F9<>"",G9<>""),F9*G9,"") -> 3 | I9: =IF(H9="","",IF(H9>=12,"🔴 Critique",IF(H9>=8,"🟠 Élevé",IF(H9>=4,"🟡 Modéré","🟢 Faible")))) -> 🟢 Faible | J9: Processus de création fournisseur encadré et validé par la finance Contrôle de l’existence juridique des fournisseurs (Kbis, RIB) Séparation des tâches entre création fournisseur et validation paiements Revue périodique du fichier fournisseurs | K9: 2 | L9: 1 | M9: =IF(AND(K9<>"",L9<>""),K9*L9,"") -> 2 | N9: =IF(M9="","",IF(M9>=12,"🔴 Critique",IF(M9>=8,"🟠 Élevé",IF(M9>=4,"🟡 Modéré","🟢 Faible")))) -> 🟢 Faible
A10: C1 | B10: Commercial & Ventes | C10: Cadeau/invitation excessive pour sécuriser un contrat | D10: Un commercial offre un cadeau ou une invitation disproportionnée à un décideur chez le client pour influencer une décision d'achat. | E10: Absence de politique cadeaux formalisée, client public ou para-public | F10: 1 | G10: 3 | H10: =IF(AND(F10<>"",G10<>""),F10*G10,"") -> 3 | I10: =IF(H10="","",IF(H10>=12,"🔴 Critique",IF(H10>=8,"🟠 Élevé",IF(H10>=4,"🟡 Modéré","🟢 Faible")))) -> 🟢 Faible | J10: Politique cadeaux & invitations définissant des seuils et règles d’acceptation Formation anticorruption des équipes commerciales Obligation d’autorisation hiérarchique pour certains avantages Code de conduite diffusé aux collaborateurs | K10: 1 | L10: 2 | M10: =IF(AND(K10<>"",L10<>""),K10*L10,"") -> 2 | N10: =IF(M10="","",IF(M10>=12,"🔴 Critique",IF(M10>=8,"🟠 Élevé",IF(M10>=4,"🟡 Modéré","🟢 Faible")))) -> 🟢 Faible
A11: C2 | B11: Commercial & Ventes | C11: Commission occulte à un intermédiaire | D11: L'entreprise verse une commission à un agent commercial qui reverse tout ou partie à un décideur du client. | E11: Agent en zone TI CPI < 40, commission disproportionnée, pas de contrat formalisé | F11: 1 | G11: 3 | H11: =IF(AND(F11<>"",G11<>""),F11*G11,"") -> 3 | I11: =IF(H11="","",IF(H11>=12,"🔴 Critique",IF(H11>=8,"🟠 Élevé",IF(H11>=4,"🟡 Modéré","🟢 Faible")))) -> 🟢 Faible | J11: Contrat écrit obligatoire avec les agents commerciaux Processus de sélection et référencement des intermédiaires Validation des commissions par le management Clause anticorruption intégrée aux contrats | K11: 3 | L11: 4 | M11: =IF(AND(K11<>"",L11<>""),K11*L11,"") -> 12 | N11: =IF(M11="","",IF(M11>=12,"🔴 Critique",IF(M11>=8,"🟠 Élevé",IF(M11>=4,"🟡 Modéré","🟢 Faible")))) -> 🔴 Critique
A12: C3 | B12: Commercial & Ventes | C12: Entente lors d'un appel d'offres | D12: Des concurrents s'entendent sur les prix ou se répartissent les lots avant de répondre à un appel d'offres. | E12: Marché concentré, échanges informels entre concurrents, historique d'attribution prévisible | F12: 2 | G12: 2 | H12: =IF(AND(F12<>"",G12<>""),F12*G12,"") -> 4 | I12: =IF(H12="","",IF(H12>=12,"🔴 Critique",IF(H12>=8,"🟠 Élevé",IF(H12>=4,"🟡 Modéré","🟢 Faible")))) -> 🟡 Modéré | J12: Procédure de réponse aux appels d’offres formalisée Formation concurrence / anticorruption des équipes commerciales Cloisonnement des équipes projets Engagement de conformité dans le code de conduite | K12: 1 | L12: 1 | M12: =IF(AND(K12<>"",L12<>""),K12*L12,"") -> 1 | N12: =IF(M12="","",IF(M12>=12,"🔴 Critique",IF(M12>=8,"🟠 Élevé",IF(M12>=4,"🟡 Modéré","🟢 Faible")))) -> 🟢 Faible
A13: C4 | B13: Commercial & Ventes | C13: Corruption d'agent public pour obtenir un marché | D13: Un commercial ou un intermédiaire verse un pot-de-vin à un agent public pour obtenir un marché public ou une autorisation. | E13: Zone géographique à risque, secteur BTP/défense/énergie, interaction directe avec décideur public | F13: 3 | G13: 3 | H13: =IF(AND(F13<>"",G13<>""),F13*G13,"") -> 9 | I13: =IF(H13="","",IF(H13>=12,"🔴 Critique",IF(H13>=8,"🟠 Élevé",IF(H13>=4,"🟡 Modéré","🟢 Faible")))) -> 🟠 Élevé | J13: Interdiction formelle de toute forme de corruption dans le code de conduite Formation anticorruption ciblée sur les relations avec le secteur public Clauses anticorruption dans les contrats avec intermédiaires Validation hiérarchique des offres sur marchés publics | K13: 4 | L13: 3 | M13: =IF(AND(K13<>"",L13<>""),K13*L13,"") -> 12 | N13: =IF(M13="","",IF(M13>=12,"🔴 Critique",IF(M13>=8,"🟠 Élevé",IF(M13>=4,"🟡 Modéré","🟢 Faible")))) -> 🔴 Critique
A14: C5 | B14: Commercial & Ventes | C14: Conditions commerciales de faveur injustifiées | D14: Octroi de remises, délais ou conditions anormalement favorables en échange d'un avantage personnel pour le commercial. | E14: Autonomie commerciale élevée, absence de grille tarifaire, pas de validation hiérarchique sur les remises | F14: 2 | G14: 3 | H14: =IF(AND(F14<>"",G14<>""),F14*G14,"") -> 6 | I14: =IF(H14="","",IF(H14>=12,"🔴 Critique",IF(H14>=8,"🟠 Élevé",IF(H14>=4,"🟡 Modéré","🟢 Faible")))) -> 🟡 Modéré | J14: Grille de remises et conditions commerciales définie Validation hiérarchique des remises exceptionnelles Traçabilité des décisions commerciales Revue périodique des marges par la finance | K14: 4 | L14: 2 | M14: =IF(AND(K14<>"",L14<>""),K14*L14,"") -> 8 | N14: =IF(M14="","",IF(M14>=12,"🔴 Critique",IF(M14>=8,"🟠 Élevé",IF(M14>=4,"🟡 Modéré","🟢 Faible")))) -> 🟠 Élevé
A15: R1 | B15: RH & Recrutement | C15: Embauche de complaisance | D15: Recrutement ou promotion d'un proche d'un décideur externe (client, fournisseur, agent public) en échange d'un avantage commercial. | E15: Absence de processus de recrutement formalisé, postes non publiés | F15: 1 | G15: 3 | H15: =IF(AND(F15<>"",G15<>""),F15*G15,"") -> 3 | I15: =IF(H15="","",IF(H15>=12,"🔴 Critique",IF(H15>=8,"🟠 Élevé",IF(H15>=4,"🟡 Modéré","🟢 Faible")))) -> 🟢 Faible | J15: Processus de recrutement encadré et documenté Validation RH systématique des recrutements Publication des postes et entretiens multiples Code de conduite interdisant les pratiques de favoritisme | K15: 1 | L15: 2 | M15: =IF(AND(K15<>"",L15<>""),K15*L15,"") -> 2 | N15: =IF(M15="","",IF(M15>=12,"🔴 Critique",IF(M15>=8,"🟠 Élevé",IF(M15>=4,"🟡 Modéré","🟢 Faible")))) -> 🟢 Faible
A16: R2 | B16: RH & Recrutement | C16: Rémunération occulte via emploi fictif | D16: Embauche d'un fonctionnaire/élu (ou de son proche) à un poste sans réalité opérationnelle. | E16: Consultant externe sans livrable vérifiable, poste créé ad hoc | F16: 2 | G16: 1 | H16: =IF(AND(F16<>"",G16<>""),F16*G16,"") -> 2 | I16: =IF(H16="","",IF(H16>=12,"🔴 Critique",IF(H16>=8,"🟠 Élevé",IF(H16>=4,"🟡 Modéré","🟢 Faible")))) -> 🟢 Faible | J16: Fiches de poste formalisées et validées Validation RH et hiérarchique des recrutements Suivi des livrables ou activités du poste Audit ponctuel de certains contrats ou fonctions sensibles | K16: 3 | L16: 4 | M16: =IF(AND(K16<>"",L16<>""),K16*L16,"") -> 12 | N16: =IF(M16="","",IF(M16>=12,"🔴 Critique",IF(M16>=8,"🟠 Élevé",IF(M16>=4,"🟡 Modéré","🟢 Faible")))) -> 🔴 Critique
... A36: P5 | B36: Relations agents publics | C36: Pantouflage non déclaré | D36: Un ancien fonctionnaire rejoint l'entreprise et utilise son réseau et informations privilégiées sans respecter les obligations déontologiques (HATVP). | E36: Recrutement d'anciens régulateurs du secteur, absence de vérification des obligations de départ | F36: 1 | G36: 4 | H36: =IF(AND(F36<>"",G36<>""),F36*G36,"") -> 4 | I36: =IF(H36="","",IF(H36>=12,"🔴 Critique",IF(H36>=8,"🟠 Élevé",IF(H36>=4,"🟡 Modéré","🟢 Faible")))) -> 🟡 Modéré | J36: Code de conduite et règles déontologiques Validation RH des recrutements sensibles Vérification partielle des obligations HATVP Sensibilisation des managers (encore limitée) | K36: 2 | L36: 2 | M36: =IF(AND(K36<>"",L36<>""),K36*L36,"") -> 4 | N36: =IF(M36="","",IF(M36>=12,"🔴 Critique",IF(M36>=8,"🟠 Élevé",IF(M36>=4,"🟡 Modéré","🟢 Faible")))) -> 🟡 Modéré

Sheet 2. Achats
A1: CARTOGRAPHIE DES RISQUES : PROCESSUS ACHATS & APPROVISIONNEMENT
A2: 💡 Les scénarios ci-dessous sont des EXEMPLES. Adaptez-les à votre entreprise, ajoutez vos propres scénarios et supprimez ceux non pertinents.
A4: N° | B4: Scénario de corruption | C4: Description du risque | D4: Facteurs aggravants | E4: Probabilité (1-4) | F4: Impact (1-4) | G4: Score brut | H4: Niveau brut | I4: Mesures de prévention existantes | J4: Probabilité réelle (1-4) | K4: Impact réel (1-4) | L4: Score réel | M4: Niveau réel | N4: Actions correctives / Gap
A5: A1 | B5: Pot-de-vin fournisseur | C5: Un acheteur favorise un fournisseur en échange d'une rétrocommission ou d'un avantage personnel (voyage, cadeau, emploi d'un proche). | D5: Fournisseur unique / pas de mise en concurrence, montant élevé, zone géographique à risque | E5: 1 | F5: 3 | G5: =IF(AND(E5<>"",F5<>""),E5*F5,"") -> 3 | H5: =IF(G5="","",IF(G5>=12,"🔴 Critique",IF(G5>=8,"🟠 Élevé",IF(G5>=4,"🟡 Modéré","🟢 Faible")))) -> 🟢 Faible | L5: =IF(AND(J5<>"",K5<>""),J5*K5,"") | M5: =IF(L5="","",IF(L5>=12,"🔴 Critique",IF(L5>=8,"🟠 Élevé",IF(L5>=4,"🟡 Modéré","🟢 Faible"))))
A6: A2 | B6: Surfacturation complice | C6: Un fournisseur surfacture une prestation avec l'accord d'un collaborateur interne qui valide la facture ; l'écart est partagé. | D6: Prestation intellectuelle (difficile à vérifier), absence de bon de commande préalable | G6: =IF(AND(E6<>"",F6<>""),E6*F6,"") | H6: =IF(G6="","",IF(G6>=12,"🔴 Critique",IF(G6>=8,"🟠 Élevé",IF(G6>=4,"🟡 Modéré","🟢 Faible")))) | L6: =IF(AND(J6<>"",K6<>""),J6*K6,"") | M6: =IF(L6="","",IF(L6>=12,"🔴 Critique",IF(L6>=8,"🟠 Élevé",IF(L6>=4,"🟡 Modéré","🟢 Faible"))))
A7: A3 | B7: Fractionnement de commandes | C7: Un acheteur fractionne volontairement des commandes pour rester sous les seuils d'approbation et éviter les contrôles. | D7: Seuils de validation élevés, pas de contrôle de cumul par fournisseur | G7: =IF(AND(E7<>"",F7<>""),E7*F7,"") | H7: =IF(G7="","",IF(G7>=12,"🔴 Critique",IF(G7>=8,"🟠 Élevé",IF(G7>=4,"🟡 Modéré","🟢 Faible")))) | L7: =IF(AND(J7<>"",K7<>""),J7*K7,"") | M7: =IF(L7="","",IF(L7>=12,"🔴 Critique",IF(L7>=8,"🟠 Élevé",IF(L7>=4,"🟡 Modéré","🟢 Faible"))))
A8: A4 | B8: Conflit d'intérêts achats | C8: Un collaborateur en charge des achats a un lien familial, amical ou financier avec un fournisseur sans le déclarer. | D8: Absence de registre des conflits d'intérêts, secteur à forte sous-traitance | G8: =IF(AND(E8<>"",F8<>""),E8*F8,"") | H8: =IF(G8="","",IF(G8>=12,"🔴 Critique",IF(G8>=8,"🟠 Élevé",IF(G8>=4,"🟡 Modéré","🟢 Faible")))) | L8: =IF(AND(J8<>"",K8<>""),J8*K8,"") | M8: =IF(L8="","",IF(L8>=12,"🔴 Critique",IF(L8>=8,"🟠 Élevé",IF(L8>=4,"🟡 Modéré","🟢 Faible"))))
A9: A5 | B9: Faux fournisseur / société écran | C9: Création d'un fournisseur fictif par un collaborateur interne pour détourner des fonds via de fausses factures. | D9: Processus de référencement fournisseur faible, contrôles comptables insuffisants | G9: =IF(AND(E9<>"",F9<>""),E9*F9,"") | H9: =IF(G9="","",IF(G9>=12,"🔴 Critique",IF(G9>=8,"🟠 Élevé",IF(G9>=4,"🟡 Modéré","🟢 Faible")))) | L9: =IF(AND(J9<>"",K9<>""),J9*K9,"") | M9: =IF(L9="","",IF(L9>=12,"🔴 Critique",IF(L9>=8,"🟠 Élevé",IF(L9>=4,"🟡 Modéré","🟢 Faible"))))
G10: =IF(AND(E10<>"",F10<>""),E10*F10,"") | H10: =IF(G10="","",IF(G10>=12,"🔴 Critique",IF(G10>=8,"🟠 Élevé",IF(G10>=4,"🟡 Modéré","🟢 Faible")))) | L10: =IF(AND(J10<>"",K10<>""),J10*K10,"") | M10: =IF(L10="","",IF(L10>=12,"🔴 Critique",IF(L10>=8,"🟠 Élevé",IF(L10>=4,"🟡 Modéré","🟢 Faible"))))
G11: =IF(AND(E11<>"",F11<>""),E11*F11,"") | H11: =IF(G11="","",IF(G11>=12,"🔴 Critique",IF(G11>=8,"🟠 Élevé",IF(G11>=4,"🟡 Modéré","🟢 Faible")))) | L11: =IF(AND(J11<>"",K11<>""),J11*K11,"") | M11: =IF(L11="","",IF(L11>=12,"🔴 Critique",IF(L11>=8,"🟠 Élevé",IF(L11>=4,"🟡 Modéré","🟢 Faible"))))
G12: =IF(AND(E12<>"",F12<>""),E12*F12,"") | H12: =IF(G12="","",IF(G12>=12,"🔴 Critique",IF(G12>=8,"🟠 Élevé",IF(G12>=4,"🟡 Modéré","🟢 Faible")))) | L12: =IF(AND(J12<>"",K12<>""),J12*K12,"") | M12: =IF(L12="","",IF(L12>=12,"🔴 Critique",IF(L12>=8,"🟠 Élevé",IF(L12>=4,"🟡 Modéré","🟢 Faible"))))
G13: =IF(AND(E13<>"",F13<>""),E13*F13,"") | H13: =IF(G13="","",IF(G13>=12,"🔴 Critique",IF(G13>=8,"🟠 Élevé",IF(G13>=4,"🟡 Modéré","🟢 Faible")))) | L13: =IF(AND(J13<>"",K13<>""),J13*K13,"") | M13: =IF(L13="","",IF(L13>=12,"🔴 Critique",IF(L13>=8,"🟠 Élevé",IF(L13>=4,"🟡 Modéré","🟢 Faible"))))
G14: =IF(AND(E14<>"",F14<>""),E14*F14,"") | H14: =IF(G14="","",IF(G14>=12,"🔴 Critique",IF(G14>=8,"🟠 Élevé",IF(G14>=4,"🟡 Modéré","🟢 Faible")))) | L14: =IF(AND(J14<>"",K14<>""),J14*K14,"") | M14: =IF(L14="","",IF(L14>=12,"🔴 Critique",IF(L14>=8,"🟠 Élevé",IF(L14>=4,"🟡 Modéré","🟢 Faible"))))

Sheet 3. Commercial
A1: CARTOGRAPHIE DES RISQUES : PROCESSUS COMMERCIAL & VENTES
A2: 💡 Les scénarios ci-dessous sont des EXEMPLES. Adaptez-les à votre entreprise, ajoutez vos propres scénarios et supprimez ceux non pertinents.
A4: N° | B4: Scénario de corruption | C4: Description du risque | D4: Facteurs aggravants | E4: Probabilité (1-4) | F4: Impact (1-4) | G4: Score brut | H4: Niveau brut | I4: Mesures de prévention existantes | J4: Probabilité réelle (1-4) | K4: Impact réel (1-4) | L4: Score réel | M4: Niveau réel | N4: Actions correctives / Gap
A5: C1 | B5: Cadeau/invitation excessive pour sécuriser un contrat | C5: Un commercial offre un cadeau ou une invitation disproportionnée à un décideur chez le client pour influencer une décision d'achat. | D5: Absence de politique cadeaux formalisée, client public ou para-public | G5: =IF(AND(E5<>"",F5<>""),E5*F5,"") | H5: =IF(G5="","",IF(G5>=12,"🔴 Critique",IF(G5>=8,"🟠 Élevé",IF(G5>=4,"🟡 Modéré","🟢 Faible")))) | L5: =IF(AND(J5<>"",K5<>""),J5*K5,"") | M5: =IF(L5="","",IF(L5>=12,"🔴 Critique",IF(L5>=8,"🟠 Élevé",IF(L5>=4,"🟡 Modéré","🟢 Faible"))))
A6: C2 | B6: Commission occulte à un intermédiaire | C6: L'entreprise verse une commission à un agent commercial qui reverse tout ou partie à un décideur du client. | D6: Agent en zone TI CPI < 40, commission disproportionnée, pas de contrat formalisé | G6: =IF(AND(E6<>"",F6<>""),E6*F6,"") | H6: =IF(G6="","",IF(G6>=12,"🔴 Critique",IF(G6>=8,"🟠 Élevé",IF(G6>=4,"🟡 Modéré","🟢 Faible")))) | L6: =IF(AND(J6<>"",K6<>""),J6*K6,"") | M6: =IF(L6="","",IF(L6>=12,"🔴 Critique",IF(L6>=8,"🟠 Élevé",IF(L6>=4,"🟡 Modéré","🟢 Faible"))))
A7: C3 | B7: Entente lors d'un appel d'offres | C7: Des concurrents s'entendent sur les prix ou se répartissent les lots avant de répondre à un appel d'offres. | D7: Marché concentré, échanges informels entre concurrents, historique d'attribution prévisible | G7: =IF(AND(E7<>"",F7<>""),E7*F7,"") | H7: =IF(G7="","",IF(G7>=12,"🔴 Critique",IF(G7>=8,"🟠 Élevé",IF(G7>=4,"🟡 Modéré","🟢 Faible")))) | L7: =IF(AND(J7<>"",K7<>""),J7*K7,"") | M7: =IF(L7="","",IF(L7>=12,"🔴 Critique",IF(L7>=8,"🟠 Élevé",IF(L7>=4,"🟡 Modéré","🟢 Faible"))))
A8: C4 | B8: Corruption d'agent public pour obtenir un marché | C8: Un commercial ou un intermédiaire verse un pot-de-vin à un agent public pour obtenir un marché public ou une autorisation. | D8: Zone géographique à risque, secteur BTP/défense/énergie, interaction directe avec décideur public | G8: =IF(AND(E8<>"",F8<>""),E8*F8,"") | H8: =IF(G8="","",IF(G8>=12,"🔴 Critique",IF(G8>=8,"🟠 Élevé",IF(G8>=4,"🟡 Modéré","🟢 Faible")))) | L8: =IF(AND(J8<>"",K8<>""),J8*K8,"") | M8: =IF(L8="","",IF(L8>=12,"🔴 Critique",IF(L8>=8,"🟠 Élevé",IF(L8>=4,"🟡 Modéré","🟢 Faible"))))
A9: C5 | B9: Conditions commerciales de faveur injustifiées | C9: Octroi de remises, délais ou conditions anormalement favorables en échange d'un avantage personnel pour le commercial. | D9: Autonomie commerciale élevée, absence de grille tarifaire, pas de validation hiérarchique sur les remises | G9: =IF(AND(E9<>"",F9<>""),E9*F9,"") | H9: =IF(G9="","",IF(G9>=12,"🔴 Critique",IF(G9>=8,"🟠 Élevé",IF(G9>=4,"🟡 Modéré","🟢 Faible")))) | L9: =IF(AND(J9<>"",K9<>""),J9*K9,"") | M9: =IF(L9="","",IF(L9>=12,"🔴 Critique",IF(L9>=8,"🟠 Élevé",IF(L9>=4,"🟡 Modéré","🟢 Faible"))))
G10: =IF(AND(E10<>"",F10<>""),E10*F10,"") | H10: =IF(G10="","",IF(G10>=12,"🔴 Critique",IF(G10>=8,"🟠 Élevé",IF(G10>=4,"🟡 Modéré","🟢 Faible")))) | L10: =IF(AND(J10<>"",K10<>""),J10*K10,"") | M10: =IF(L10="","",IF(L10>=12,"🔴 Critique",IF(L10>=8,"🟠 Élevé",IF(L10>=4,"🟡 Modéré","🟢 Faible"))))
G11: =IF(AND(E11<>"",F11<>""),E11*F11,"") | H11: =IF(G11="","",IF(G11>=12,"🔴 Critique",IF(G11>=8,"🟠 Élevé",IF(G11>=4,"🟡 Modéré","🟢 Faible")))) | L11: =IF(AND(J11<>"",K11<>""),J11*K11,"") | M11: =IF(L11="","",IF(L11>=12,"🔴 Critique",IF(L11>=8,"🟠 Élevé",IF(L11>=4,"🟡 Modéré","🟢 Faible"))))
G12: =IF(AND(E12<>"",F12<>""),E12*F12,"") | H12: =IF(G12="","",IF(G12>=12,"🔴 Critique",IF(G12>=8,"🟠 Élevé",IF(G12>=4,"🟡 Modéré","🟢 Faible")))) | L12: =IF(AND(J12<>"",K12<>""),J12*K12,"") | M12: =IF(L12="","",IF(L12>=12,"🔴 Critique",IF(L12>=8,"🟠 Élevé",IF(L12>=4,"🟡 Modéré","🟢 Faible"))))
G13: =IF(AND(E13<>"",F13<>""),E13*F13,"") | H13: =IF(G13="","",IF(G13>=12,"🔴 Critique",IF(G13>=8,"🟠 Élevé",IF(G13>=4,"🟡 Modéré","🟢 Faible")))) | L13: =IF(AND(J13<>"",K13<>""),J13*K13,"") | M13: =IF(L13="","",IF(L13>=12,"🔴 Critique",IF(L13>=8,"🟠 Élevé",IF(L13>=4,"🟡 Modéré","🟢 Faible"))))
G14: =IF(AND(E14<>"",F14<>""),E14*F14,"") | H14: =IF(G14="","",IF(G14>=12,"🔴 Critique",IF(G14>=8,"🟠 Élevé",IF(G14>=4,"🟡 Modéré","🟢 Faible")))) | L14: =IF(AND(J14<>"",K14<>""),J14*K14,"") | M14: =IF(L14="","",IF(L14>=12,"🔴 Critique",IF(L14>=8,"🟠 Élevé",IF(L14>=4,"🟡 Modéré","🟢 Faible"))))

Sheet 4. RH
A1: CARTOGRAPHIE DES RISQUES : PROCESSUS RH & RECRUTEMENT
A2: 💡 Les scénarios ci-dessous sont des EXEMPLES. Adaptez-les à votre entreprise, ajoutez vos propres scénarios et supprimez ceux non pertinents.
A4: N° | B4: Scénario de corruption | C4: Description du risque | D4: Facteurs aggravants | E4: Probabilité (1-4) | F4: Impact (1-4) | G4: Score brut | H4: Niveau brut | I4: Mesures de prévention existantes | J4: Probabilité réelle (1-4) | K4: Impact réel (1-4) | L4: Score réel | M4: Niveau réel | N4: Actions correctives / Gap
A5: R1 | B5: Embauche de complaisance | C5: Recrutement ou promotion d'un proche d'un décideur externe (client, fournisseur, agent public) en échange d'un avantage commercial. | D5: Absence de processus de recrutement formalisé, postes non publiés | G5: =IF(AND(E5<>"",F5<>""),E5*F5,"") | H5: =IF(G5="","",IF(G5>=12,"🔴 Critique",IF(G5>=8,"🟠 Élevé",IF(G5>=4,"🟡 Modéré","🟢 Faible")))) | L5: =IF(AND(J5<>"",K5<>""),J5*K5,"") | M5: =IF(L5="","",IF(L5>=12,"🔴 Critique",IF(L5>=8,"🟠 Élevé",IF(L5>=4,"🟡 Modéré","🟢 Faible"))))
A6: R2 | B6: Rémunération occulte via emploi fictif | C6: Embauche d'un fonctionnaire/élu (ou de son proche) à un poste sans réalité opérationnelle. | D6: Consultant externe sans livrable vérifiable, poste créé ad hoc | G6: =IF(AND(E6<>"",F6<>""),E6*F6,"") | H6: =IF(G6="","",IF(G6>=12,"🔴 Critique",IF(G6>=8,"🟠 Élevé",IF(G6>=4,"🟡 Modéré","🟢 Faible")))) | L6: =IF(AND(J6<>"",K6<>""),J6*K6,"") | M6: =IF(L6="","",IF(L6>=12,"🔴 Critique",IF(L6>=8,"🟠 Élevé",IF(L6>=4,"🟡 Modéré","🟢 Faible"))))
A7: R3 | B7: Conflit d'intérêts non déclaré en recrutement | C7: Un manager recrute un membre de sa famille ou un ami proche sans le déclarer, créant un biais dans les décisions RH. | D7: Pas de politique de déclaration des liens, entreprise familiale, filiale à l'étranger | G7: =IF(AND(E7<>"",F7<>""),E7*F7,"") | H7: =IF(G7="","",IF(G7>=12,"🔴 Critique",IF(G7>=8,"🟠 Élevé",IF(G7>=4,"🟡 Modéré","🟢 Faible")))) | L7: =IF(AND(J7<>"",K7<>""),J7*K7,"") | M7: =IF(L7="","",IF(L7>=12,"🔴 Critique",IF(L7>=8,"🟠 Élevé",IF(L7>=4,"🟡 Modéré","🟢 Faible"))))
A8: R4 | B8: Manipulation des primes et bonus | C8: Un manager attribue des primes discrétionnaires à des collaborateurs en échange de leur silence ou complicité. | D8: Enveloppes de primes non encadrées, critères d'attribution opaques | G8: =IF(AND(E8<>"",F8<>""),E8*F8,"") | H8: =IF(G8="","",IF(G8>=12,"🔴 Critique",IF(G8>=8,"🟠 Élevé",IF(G8>=4,"🟡 Modéré","🟢 Faible")))) | L8: =IF(AND(J8<>"",K8<>""),J8*K8,"") | M8: =IF(L8="","",IF(L8>=12,"🔴 Critique",IF(L8>=8,"🟠 Élevé",IF(L8>=4,"🟡 Modéré","🟢 Faible"))))
G9: =IF(AND(E9<>"",F9<>""),E9*F9,"") | H9: =IF(G9="","",IF(G9>=12,"🔴 Critique",IF(G9>=8,"🟠 Élevé",IF(G9>=4,"🟡 Modéré","🟢 Faible")))) | L9: =IF(AND(J9<>"",K9<>""),J9*K9,"") | M9: =IF(L9="","",IF(L9>=12,"🔴 Critique",IF(L9>=8,"🟠 Élevé",IF(L9>=4,"🟡 Modéré","🟢 Faible"))))
G10: =IF(AND(E10<>"",F10<>""),E10*F10,"") | H10: =IF(G10="","",IF(G10>=12,"🔴 Critique",IF(G10>=8,"🟠 Élevé",IF(G10>=4,"🟡 Modéré","🟢 Faible")))) | L10: =IF(AND(J10<>"",K10<>""),J10*K10,"") | M10: =IF(L10="","",IF(L10>=12,"🔴 Critique",IF(L10>=8,"🟠 Élevé",IF(L10>=4,"🟡 Modéré","🟢 Faible"))))
G11: =IF(AND(E11<>"",F11<>""),E11*F11,"") | H11: =IF(G11="","",IF(G11>=12,"🔴 Critique",IF(G11>=8,"🟠 Élevé",IF(G11>=4,"🟡 Modéré","🟢 Faible")))) | L11: =IF(AND(J11<>"",K11<>""),J11*K11,"") | M11: =IF(L11="","",IF(L11>=12,"🔴 Critique",IF(L11>=8,"🟠 Élevé",IF(L11>=4,"🟡 Modéré","🟢 Faible"))))
G12: =IF(AND(E12<>"",F12<>""),E12*F12,"") | H12: =IF(G12="","",IF(G12>=12,"🔴 Critique",IF(G12>=8,"🟠 Élevé",IF(G12>=4,"🟡 Modéré","🟢 Faible")))) | L12: =IF(AND(J12<>"",K12<>""),J12*K12,"") | M12: =IF(L12="","",IF(L12>=12,"🔴 Critique",IF(L12>=8,"🟠 Élevé",IF(L12>=4,"🟡 Modéré","🟢 Faible"))))
G13: =IF(AND(E13<>"",F13<>""),E13*F13,"") | H13: =IF(G13="","",IF(G13>=12,"🔴 Critique",IF(G13>=8,"🟠 Élevé",IF(G13>=4,"🟡 Modéré","🟢 Faible")))) | L13: =IF(AND(J13<>"",K13<>""),J13*K13,"") | M13: =IF(L13="","",IF(L13>=12,"🔴 Critique",IF(L13>=8,"🟠 Élevé",IF(L13>=4,"🟡 Modéré","🟢 Faible"))))
G14: =IF(AND(E14<>"",F14<>""),E14*F14,"") | H14: =IF(G14="","",IF(G14>=12,"🔴 Critique",IF(G14>=8,"🟠 Élevé",IF(G14>=4,"🟡 Modéré","🟢 Faible")))) | L14: =IF(AND(J14<>"",K14<>""),J14*K14,"") | M14: =IF(L14="","",IF(L14>=12,"🔴 Critique",IF(L14>=8,"🟠 Élevé",IF(L14>=4,"🟡 Modéré","🟢 Faible"))))

Sheet 5. Finance
A1: CARTOGRAPHIE DES RISQUES : PROCESSUS FINANCE & COMPTABILITÉ
A2: 💡 Les scénarios ci-dessous sont des EXEMPLES. Adaptez-les à votre entreprise, ajoutez vos propres scénarios et supprimez ceux non pertinents.
A4: N° | B4: Scénario de corruption | C4: Description du risque | D4: Facteurs aggravants | E4: Probabilité (1-4) | F4: Impact (1-4) | G4: Score brut | H4: Niveau brut | I4: Mesures de prévention existantes | J4: Probabilité réelle (1-4) | K4: Impact réel (1-4) | L4: Score réel | M4: Niveau réel | N4: Actions correctives / Gap
A5: F1 | B5: Paiement de facilitation | C5: L'entreprise effectue un paiement à un agent public étranger pour accélérer une procédure administrative (dédouanement, visa, autorisation). | D5: Opérations dans des pays à risque, pression commerciale sur les délais | G5: =IF(AND(E5<>"",F5<>""),E5*F5,"") | H5: =IF(G5="","",IF(G5>=12,"🔴 Critique",IF(G5>=8,"🟠 Élevé",IF(G5>=4,"🟡 Modéré","🟢 Faible")))) | L5: =IF(AND(J5<>"",K5<>""),J5*K5,"") | M5: =IF(L5="","",IF(L5>=12,"🔴 Critique",IF(L5>=8,"🟠 Élevé",IF(L5>=4,"🟡 Modéré","🟢 Faible"))))
A6: F2 | B6: Manipulation d'écritures comptables | C6: Des paiements illicites sont enregistrés sous des libellés anodins (frais de conseil, honoraires, commissions) pour dissimuler des pots-de-vin. | D6: Absence de contrôle sur les comptes de charges sensibles (6226, 6228, 622), validation par une seule personne | G6: =IF(AND(E6<>"",F6<>""),E6*F6,"") | H6: =IF(G6="","",IF(G6>=12,"🔴 Critique",IF(G6>=8,"🟠 Élevé",IF(G6>=4,"🟡 Modéré","🟢 Faible")))) | L6: =IF(AND(J6<>"",K6<>""),J6*K6,"") | M6: =IF(L6="","",IF(L6>=12,"🔴 Critique",IF(L6>=8,"🟠 Élevé",IF(L6>=4,"🟡 Modéré","🟢 Faible"))))
A7: F3 | B7: Notes de frais frauduleuses | C7: Un collaborateur gonfle ou falsifie ses notes de frais pour compenser un avantage indu donné à un tiers. | D7: Plafonds de notes de frais élevés, validation automatique sous un seuil, pas de justificatifs systématiques | G7: =IF(AND(E7<>"",F7<>""),E7*F7,"") | H7: =IF(G7="","",IF(G7>=12,"🔴 Critique",IF(G7>=8,"🟠 Élevé",IF(G7>=4,"🟡 Modéré","🟢 Faible")))) | L7: =IF(AND(J7<>"",K7<>""),J7*K7,"") | M7: =IF(L7="","",IF(L7>=12,"🔴 Critique",IF(L7>=8,"🟠 Élevé",IF(L7>=4,"🟡 Modéré","🟢 Faible"))))
A8: F4 | B8: Détournement via prestataire fictif | C8: Un collaborateur ayant accès aux systèmes de paiement crée un fournisseur fictif et ordonne des virements. | D8: Séparation des tâches insuffisante, faible contrôle des RIB | G8: =IF(AND(E8<>"",F8<>""),E8*F8,"") | H8: =IF(G8="","",IF(G8>=12,"🔴 Critique",IF(G8>=8,"🟠 Élevé",IF(G8>=4,"🟡 Modéré","🟢 Faible")))) | L8: =IF(AND(J8<>"",K8<>""),J8*K8,"") | M8: =IF(L8="","",IF(L8>=12,"🔴 Critique",IF(L8>=8,"🟠 Élevé",IF(L8>=4,"🟡 Modéré","🟢 Faible"))))
A9: F5 | B9: Paiement vers un pays tiers sans justification | C9: Un paiement est effectué vers un compte dans un pays différent de celui du fournisseur ou de la prestation, sans justification documentée. | D9: Pays à risque, opérations internationales complexes, holding intermédiaires | G9: =IF(AND(E9<>"",F9<>""),E9*F9,"") | H9: =IF(G9="","",IF(G9>=12,"🔴 Critique",IF(G9>=8,"🟠 Élevé",IF(G9>=4,"🟡 Modéré","🟢 Faible")))) | L9: =IF(AND(J9<>"",K9<>""),J9*K9,"") | M9: =IF(L9="","",IF(L9>=12,"🔴 Critique",IF(L9>=8,"🟠 Élevé",IF(L9>=4,"🟡 Modéré","🟢 Faible"))))
G10: =IF(AND(E10<>"",F10<>""),E10*F10,"") | H10: =IF(G10="","",IF(G10>=12,"🔴 Critique",IF(G10>=8,"🟠 Élevé",IF(G10>=4,"🟡 Modéré","🟢 Faible")))) | L10: =IF(AND(J10<>"",K10<>""),J10*K10,"") | M10: =IF(L10="","",IF(L10>=12,"🔴 Critique",IF(L10>=8,"🟠 Élevé",IF(L10>=4,"🟡 Modéré","🟢 Faible"))))
G11: =IF(AND(E11<>"",F11<>""),E11*F11,"") | H11: =IF(G11="","",IF(G11>=12,"🔴 Critique",IF(G11>=8,"🟠 Élevé",IF(G11>=4,"🟡 Modéré","🟢 Faible")))) | L11: =IF(AND(J11<>"",K11<>""),J11*K11,"") | M11: =IF(L11="","",IF(L11>=12,"🔴 Critique",IF(L11>=8,"🟠 Élevé",IF(L11>=4,"🟡 Modéré","🟢 Faible"))))
G12: =IF(AND(E12<>"",F12<>""),E12*F12,"") | H12: =IF(G12="","",IF(G12>=12,"🔴 Critique",IF(G12>=8,"🟠 Élevé",IF(G12>=4,"🟡 Modéré","🟢 Faible")))) | L12: =IF(AND(J12<>"",K12<>""),J12*K12,"") | M12: =IF(L12="","",IF(L12>=12,"🔴 Critique",IF(L12>=8,"🟠 Élevé",IF(L12>=4,"🟡 Modéré","🟢 Faible"))))
G13: =IF(AND(E13<>"",F13<>""),E13*F13,"") | H13: =IF(G13="","",IF(G13>=12,"🔴 Critique",IF(G13>=8,"🟠 Élevé",IF(G13>=4,"🟡 Modéré","🟢 Faible")))) | L13: =IF(AND(J13<>"",K13<>""),J13*K13,"") | M13: =IF(L13="","",IF(L13>=12,"🔴 Critique",IF(L13>=8,"🟠 Élevé",IF(L13>=4,"🟡 Modéré","🟢 Faible"))))
G14: =IF(AND(E14<>"",F14<>""),E14*F14,"") | H14: =IF(G14="","",IF(G14>=12,"🔴 Critique",IF(G14>=8,"🟠 Élevé",IF(G14>=4,"🟡 Modéré","🟢 Faible")))) | L14: =IF(AND(J14<>"",K14<>""),J14*K14,"") | M14: =IF(L14="","",IF(L14>=12,"🔴 Critique",IF(L14>=8,"🟠 Élevé",IF(L14>=4,"🟡 Modéré","🟢 Faible"))))

Sheet 6. M&A - JV
A1: CARTOGRAPHIE DES RISQUES : PROCESSUS M&A, PARTENARIATS & JV
A2: 💡 Les scénarios ci-dessous sont des EXEMPLES. Adaptez-les à votre entreprise, ajoutez vos propres scénarios et supprimez ceux non pertinents.
A4: N° | B4: Scénario de corruption | C4: Description du risque | D4: Facteurs aggravants | E4: Probabilité (1-4) | F4: Impact (1-4) | G4: Score brut | H4: Niveau brut | I4: Mesures de prévention existantes | J4: Probabilité réelle (1-4) | K4: Impact réel (1-4) | L4: Score réel | M4: Niveau réel | N4: Actions correctives / Gap
A5: M1 | B5: Acquisition avec passif de corruption non détecté | C5: L'entreprise acquiert une cible sans due diligence anticorruption suffisante et hérite de risques (CJIP, poursuites, pratiques corruptives). | D5: Acquisition rapide, zone géo à risque, secteur exposé, due diligence limitée au financier | G5: =IF(AND(E5<>"",F5<>""),E5*F5,"") | H5: =IF(G5="","",IF(G5>=12,"🔴 Critique",IF(G5>=8,"🟠 Élevé",IF(G5>=4,"🟡 Modéré","🟢 Faible")))) | L5: =IF(AND(J5<>"",K5<>""),J5*K5,"") | M5: =IF(L5="","",IF(L5>=12,"🔴 Critique",IF(L5>=8,"🟠 Élevé",IF(L5>=4,"🟡 Modéré","🟢 Faible"))))
A6: M2 | B6: Corruption via un partenaire de JV | C6: Le partenaire local d'une co-entreprise verse des pots-de-vin à des agents publics pour le compte de la JV. | D6: JV dans un pays à risque, gouvernance partagée sans droit de regard sur les opérations locales | G6: =IF(AND(E6<>"",F6<>""),E6*F6,"") | H6: =IF(G6="","",IF(G6>=12,"🔴 Critique",IF(G6>=8,"🟠 Élevé",IF(G6>=4,"🟡 Modéré","🟢 Faible")))) | L6: =IF(AND(J6<>"",K6<>""),J6*K6,"") | M6: =IF(L6="","",IF(L6>=12,"🔴 Critique",IF(L6>=8,"🟠 Élevé",IF(L6>=4,"🟡 Modéré","🟢 Faible"))))
A7: M3 | B7: Conflit d'intérêts dans une opération M&A | C7: Un dirigeant ou administrateur a un intérêt personnel dans la cible et influence la décision d'acquisition. | D7: Absence de déclaration d'intérêts au board, opération entre parties liées | G7: =IF(AND(E7<>"",F7<>""),E7*F7,"") | H7: =IF(G7="","",IF(G7>=12,"🔴 Critique",IF(G7>=8,"🟠 Élevé",IF(G7>=4,"🟡 Modéré","🟢 Faible")))) | L7: =IF(AND(J7<>"",K7<>""),J7*K7,"") | M7: =IF(L7="","",IF(L7>=12,"🔴 Critique",IF(L7>=8,"🟠 Élevé",IF(L7>=4,"🟡 Modéré","🟢 Faible"))))
A8: M4 | B8: Surfacturation de prestations de conseil M&A | C8: Des honoraires de conseil sont gonflés et une partie rétrocédée à un décideur de l'entreprise ou de la cible. | D8: Consultant introduit par la cible, honoraires au succès disproportionnés | G8: =IF(AND(E8<>"",F8<>""),E8*F8,"") | H8: =IF(G8="","",IF(G8>=12,"🔴 Critique",IF(G8>=8,"🟠 Élevé",IF(G8>=4,"🟡 Modéré","🟢 Faible")))) | L8: =IF(AND(J8<>"",K8<>""),J8*K8,"") | M8: =IF(L8="","",IF(L8>=12,"🔴 Critique",IF(L8>=8,"🟠 Élevé",IF(L8>=4,"🟡 Modéré","🟢 Faible"))))
G9: =IF(AND(E9<>"",F9<>""),E9*F9,"") | H9: =IF(G9="","",IF(G9>=12,"🔴 Critique",IF(G9>=8,"🟠 Élevé",IF(G9>=4,"🟡 Modéré","🟢 Faible")))) | L9: =IF(AND(J9<>"",K9<>""),J9*K9,"") | M9: =IF(L9="","",IF(L9>=12,"🔴 Critique",IF(L9>=8,"🟠 Élevé",IF(L9>=4,"🟡 Modéré","🟢 Faible"))))
G10: =IF(AND(E10<>"",F10<>""),E10*F10,"") | H10: =IF(G10="","",IF(G10>=12,"🔴 Critique",IF(G10>=8,"🟠 Élevé",IF(G10>=4,"🟡 Modéré","🟢 Faible")))) | L10: =IF(AND(J10<>"",K10<>""),J10*K10,"") | M10: =IF(L10="","",IF(L10>=12,"🔴 Critique",IF(L10>=8,"🟠 Élevé",IF(L10>=4,"🟡 Modéré","🟢 Faible"))))
G11: =IF(AND(E11<>"",F11<>""),E11*F11,"") | H11: =IF(G11="","",IF(G11>=12,"🔴 Critique",IF(G11>=8,"🟠 Élevé",IF(G11>=4,"🟡 Modéré","🟢 Faible")))) | L11: =IF(AND(J11<>"",K11<>""),J11*K11,"") | M11: =IF(L11="","",IF(L11>=12,"🔴 Critique",IF(L11>=8,"🟠 Élevé",IF(L11>=4,"🟡 Modéré","🟢 Faible"))))
G12: =IF(AND(E12<>"",F12<>""),E12*F12,"") | H12: =IF(G12="","",IF(G12>=12,"🔴 Critique",IF(G12>=8,"🟠 Élevé",IF(G12>=4,"🟡 Modéré","🟢 Faible")))) | L12: =IF(AND(J12<>"",K12<>""),J12*K12,"") | M12: =IF(L12="","",IF(L12>=12,"🔴 Critique",IF(L12>=8,"🟠 Élevé",IF(L12>=4,"🟡 Modéré","🟢 Faible"))))
G13: =IF(AND(E13<>"",F13<>""),E13*F13,"") | H13: =IF(G13="","",IF(G13>=12,"🔴 Critique",IF(G13>=8,"🟠 Élevé",IF(G13>=4,"🟡 Modéré","🟢 Faible")))) | L13: =IF(AND(J13<>"",K13<>""),J13*K13,"") | M13: =IF(L13="","",IF(L13>=12,"🔴 Critique",IF(L13>=8,"🟠 Élevé",IF(L13>=4,"🟡 Modéré","🟢 Faible"))))
G14: =IF(AND(E14<>"",F14<>""),E14*F14,"") | H14: =IF(G14="","",IF(G14>=12,"🔴 Critique",IF(G14>=8,"🟠 Élevé",IF(G14>=4,"🟡 Modéré","🟢 Faible")))) | L14: =IF(AND(J14<>"",K14<>""),J14*K14,"") | M14: =IF(L14="","",IF(L14>=12,"🔴 Critique",IF(L14>=8,"🟠 Élevé",IF(L14>=4,"🟡 Modéré","🟢 Faible"))))

Sheet 7. Sponsoring
A1: CARTOGRAPHIE DES RISQUES : PROCESSUS SPONSORING, MÉCÉNAT & DONS
A2: 💡 Les scénarios ci-dessous sont des EXEMPLES. Adaptez-les à votre entreprise, ajoutez vos propres scénarios et supprimez ceux non pertinents.
A4: N° | B4: Scénario de corruption | C4: Description du risque | D4: Facteurs aggravants | E4: Probabilité (1-4) | F4: Impact (1-4) | G4: Score brut | H4: Niveau brut | I4: Mesures de prévention existantes | J4: Probabilité réelle (1-4) | K4: Impact réel (1-4) | L4: Score réel | M4: Niveau réel | N4: Actions correctives / Gap
A5: S1 | B5: Don/mécénat comme véhicule de corruption | C5: L'entreprise finance une association liée à un agent public ou décideur en échange d'un avantage (marché, autorisation, traitement favorable). | D5: Association liée à un élu ou fonctionnaire, absence de vérification de l'utilisation des fonds | G5: =IF(AND(E5<>"",F5<>""),E5*F5,"") | H5: =IF(G5="","",IF(G5>=12,"🔴 Critique",IF(G5>=8,"🟠 Élevé",IF(G5>=4,"🟡 Modéré","🟢 Faible")))) | L5: =IF(AND(J5<>"",K5<>""),J5*K5,"") | M5: =IF(L5="","",IF(L5>=12,"🔴 Critique",IF(L5>=8,"🟠 Élevé",IF(L5>=4,"🟡 Modéré","🟢 Faible"))))
A6: S2 | B6: Sponsoring comme contrepartie dissimulée | C6: L'entreprise sponsorise un événement dont les organisateurs sont liés à un décideur chez un client ou dans l'administration. | D6: Pas de politique de sponsoring formalisée, montant disproportionné, bénéficiaire opaque | G6: =IF(AND(E6<>"",F6<>""),E6*F6,"") | H6: =IF(G6="","",IF(G6>=12,"🔴 Critique",IF(G6>=8,"🟠 Élevé",IF(G6>=4,"🟡 Modéré","🟢 Faible")))) | L6: =IF(AND(J6<>"",K6<>""),J6*K6,"") | M6: =IF(L6="","",IF(L6>=12,"🔴 Critique",IF(L6>=8,"🟠 Élevé",IF(L6>=4,"🟡 Modéré","🟢 Faible"))))
A7: S3 | B7: Contributions politiques déguisées | C7: L'entreprise finance indirectement un parti ou candidat via un don à une structure intermédiaire (association, think tank). | D7: Illégal en France pour les personnes morales (art. L52-8 Code électoral), risque aggravé à l'international | G7: =IF(AND(E7<>"",F7<>""),E7*F7,"") | H7: =IF(G7="","",IF(G7>=12,"🔴 Critique",IF(G7>=8,"🟠 Élevé",IF(G7>=4,"🟡 Modéré","🟢 Faible")))) | L7: =IF(AND(J7<>"",K7<>""),J7*K7,"") | M7: =IF(L7="","",IF(L7>=12,"🔴 Critique",IF(L7>=8,"🟠 Élevé",IF(L7>=4,"🟡 Modéré","🟢 Faible"))))
A8: S4 | B8: Détournement de budget mécénat | C8: Un collaborateur détourne tout ou partie d'un budget mécénat vers une structure dont il est bénéficiaire direct ou indirect. | D8: Pas de double validation sur les dons, absence de suivi de l'utilisation des fonds | G8: =IF(AND(E8<>"",F8<>""),E8*F8,"") | H8: =IF(G8="","",IF(G8>=12,"🔴 Critique",IF(G8>=8,"🟠 Élevé",IF(G8>=4,"🟡 Modéré","🟢 Faible")))) | L8: =IF(AND(J8<>"",K8<>""),J8*K8,"") | M8: =IF(L8="","",IF(L8>=12,"🔴 Critique",IF(L8>=8,"🟠 Élevé",IF(L8>=4,"🟡 Modéré","🟢 Faible"))))
G9: =IF(AND(E9<>"",F9<>""),E9*F9,"") | H9: =IF(G9="","",IF(G9>=12,"🔴 Critique",IF(G9>=8,"🟠 Élevé",IF(G9>=4,"🟡 Modéré","🟢 Faible")))) | L9: =IF(AND(J9<>"",K9<>""),J9*K9,"") | M9: =IF(L9="","",IF(L9>=12,"🔴 Critique",IF(L9>=8,"🟠 Élevé",IF(L9>=4,"🟡 Modéré","🟢 Faible"))))
G10: =IF(AND(E10<>"",F10<>""),E10*F10,"") | H10: =IF(G10="","",IF(G10>=12,"🔴 Critique",IF(G10>=8,"🟠 Élevé",IF(G10>=4,"🟡 Modéré","🟢 Faible")))) | L10: =IF(AND(J10<>"",K10<>""),J10*K10,"") | M10: =IF(L10="","",IF(L10>=12,"🔴 Critique",IF(L10>=8,"🟠 Élevé",IF(L10>=4,"🟡 Modéré","🟢 Faible"))))
G11: =IF(AND(E11<>"",F11<>""),E11*F11,"") | H11: =IF(G11="","",IF(G11>=12,"🔴 Critique",IF(G11>=8,"🟠 Élevé",IF(G11>=4,"🟡 Modéré","🟢 Faible")))) | L11: =IF(AND(J11<>"",K11<>""),J11*K11,"") | M11: =IF(L11="","",IF(L11>=12,"🔴 Critique",IF(L11>=8,"🟠 Élevé",IF(L11>=4,"🟡 Modéré","🟢 Faible"))))
G12: =IF(AND(E12<>"",F12<>""),E12*F12,"") | H12: =IF(G12="","",IF(G12>=12,"🔴 Critique",IF(G12>=8,"🟠 Élevé",IF(G12>=4,"🟡 Modéré","🟢 Faible")))) | L12: =IF(AND(J12<>"",K12<>""),J12*K12,"") | M12: =IF(L12="","",IF(L12>=12,"🔴 Critique",IF(L12>=8,"🟠 Élevé",IF(L12>=4,"🟡 Modéré","🟢 Faible"))))
G13: =IF(AND(E13<>"",F13<>""),E13*F13,"") | H13: =IF(G13="","",IF(G13>=12,"🔴 Critique",IF(G13>=8,"🟠 Élevé",IF(G13>=4,"🟡 Modéré","🟢 Faible")))) | L13: =IF(AND(J13<>"",K13<>""),J13*K13,"") | M13: =IF(L13="","",IF(L13>=12,"🔴 Critique",IF(L13>=8,"🟠 Élevé",IF(L13>=4,"🟡 Modéré","🟢 Faible"))))
G14: =IF(AND(E14<>"",F14<>""),E14*F14,"") | H14: =IF(G14="","",IF(G14>=12,"🔴 Critique",IF(G14>=8,"🟠 Élevé",IF(G14>=4,"🟡 Modéré","🟢 Faible")))) | L14: =IF(AND(J14<>"",K14<>""),J14*K14,"") | M14: =IF(L14="","",IF(L14>=12,"🔴 Critique",IF(L14>=8,"🟠 Élevé",IF(L14>=4,"🟡 Modéré","🟢 Faible"))))

Sheet 8. Agents publics
A1: CARTOGRAPHIE DES RISQUES : PROCESSUS RELATIONS AVEC AGENTS PUBLICS
A2: 💡 Les scénarios ci-dessous sont des EXEMPLES. Adaptez-les à votre entreprise, ajoutez vos propres scénarios et supprimez ceux non pertinents.
A4: N° | B4: Scénario de corruption | C4: Description du risque | D4: Facteurs aggravants | E4: Probabilité (1-4) | F4: Impact (1-4) | G4: Score brut | H4: Niveau brut | I4: Mesures de prévention existantes | J4: Probabilité réelle (1-4) | K4: Impact réel (1-4) | L4: Score réel | M4: Niveau réel | N4: Actions correctives / Gap
A5: P1 | B5: Lobbying non encadré | C5: Un collaborateur ou consultant influence un décideur public sans que cette activité soit déclarée, documentée ou encadrée. | D5: Absence de registre de lobbying, recours à des intermédiaires non encadrés | G5: =IF(AND(E5<>"",F5<>""),E5*F5,"") | H5: =IF(G5="","",IF(G5>=12,"🔴 Critique",IF(G5>=8,"🟠 Élevé",IF(G5>=4,"🟡 Modéré","🟢 Faible")))) | L5: =IF(AND(J5<>"",K5<>""),J5*K5,"") | M5: =IF(L5="","",IF(L5>=12,"🔴 Critique",IF(L5>=8,"🟠 Élevé",IF(L5>=4,"🟡 Modéré","🟢 Faible"))))
A6: P2 | B6: Trafic d'influence via un élu ou fonctionnaire | C6: Un agent public utilise sa position pour orienter une décision en faveur de l'entreprise en échange d'un avantage. | D6: Interaction directe et fréquente avec des décideurs publics, secteur réglementé | G6: =IF(AND(E6<>"",F6<>""),E6*F6,"") | H6: =IF(G6="","",IF(G6>=12,"🔴 Critique",IF(G6>=8,"🟠 Élevé",IF(G6>=4,"🟡 Modéré","🟢 Faible")))) | L6: =IF(AND(J6<>"",K6<>""),J6*K6,"") | M6: =IF(L6="","",IF(L6>=12,"🔴 Critique",IF(L6>=8,"🟠 Élevé",IF(L6>=4,"🟡 Modéré","🟢 Faible"))))
A7: P3 | B7: Obtention frauduleuse d'autorisations | C7: L'entreprise verse un avantage à un agent public pour accélérer ou obtenir une autorisation administrative. | D7: Zone géo à risque, délais administratifs longs, enjeux financiers élevés | G7: =IF(AND(E7<>"",F7<>""),E7*F7,"") | H7: =IF(G7="","",IF(G7>=12,"🔴 Critique",IF(G7>=8,"🟠 Élevé",IF(G7>=4,"🟡 Modéré","🟢 Faible")))) | L7: =IF(AND(J7<>"",K7<>""),J7*K7,"") | M7: =IF(L7="","",IF(L7>=12,"🔴 Critique",IF(L7>=8,"🟠 Élevé",IF(L7>=4,"🟡 Modéré","🟢 Faible"))))
A8: P4 | B8: Favoritisme dans l'attribution de subventions | C8: L'entreprise bénéficie d'une subvention publique grâce à un traitement de faveur, en échange d'un avantage. | D8: Lien personnel avec le décideur, absence de mise en concurrence, subventions discrétionnaires | G8: =IF(AND(E8<>"",F8<>""),E8*F8,"") | H8: =IF(G8="","",IF(G8>=12,"🔴 Critique",IF(G8>=8,"🟠 Élevé",IF(G8>=4,"🟡 Modéré","🟢 Faible")))) | L8: =IF(AND(J8<>"",K8<>""),J8*K8,"") | M8: =IF(L8="","",IF(L8>=12,"🔴 Critique",IF(L8>=8,"🟠 Élevé",IF(L8>=4,"🟡 Modéré","🟢 Faible"))))
A9: P5 | B9: Pantouflage non déclaré | C9: Un ancien fonctionnaire rejoint l'entreprise et utilise son réseau et informations privilégiées sans respecter les obligations déontologiques (HATVP). | D9: Recrutement d'anciens régulateurs du secteur, absence de vérification des obligations de départ | G9: =IF(AND(E9<>"",F9<>""),E9*F9,"") | H9: =IF(G9="","",IF(G9>=12,"🔴 Critique",IF(G9>=8,"🟠 Élevé",IF(G9>=4,"🟡 Modéré","🟢 Faible")))) | L9: =IF(AND(J9<>"",K9<>""),J9*K9,"") | M9: =IF(L9="","",IF(L9>=12,"🔴 Critique",IF(L9>=8,"🟠 Élevé",IF(L9>=4,"🟡 Modéré","🟢 Faible"))))
G10: =IF(AND(E10<>"",F10<>""),E10*F10,"") | H10: =IF(G10="","",IF(G10>=12,"🔴 Critique",IF(G10>=8,"🟠 Élevé",IF(G10>=4,"🟡 Modéré","🟢 Faible")))) | L10: =IF(AND(J10<>"",K10<>""),J10*K10,"") | M10: =IF(L10="","",IF(L10>=12,"🔴 Critique",IF(L10>=8,"🟠 Élevé",IF(L10>=4,"🟡 Modéré","🟢 Faible"))))
G11: =IF(AND(E11<>"",F11<>""),E11*F11,"") | H11: =IF(G11="","",IF(G11>=12,"🔴 Critique",IF(G11>=8,"🟠 Élevé",IF(G11>=4,"🟡 Modéré","🟢 Faible")))) | L11: =IF(AND(J11<>"",K11<>""),J11*K11,"") | M11: =IF(L11="","",IF(L11>=12,"🔴 Critique",IF(L11>=8,"🟠 Élevé",IF(L11>=4,"🟡 Modéré","🟢 Faible"))))
G12: =IF(AND(E12<>"",F12<>""),E12*F12,"") | H12: =IF(G12="","",IF(G12>=12,"🔴 Critique",IF(G12>=8,"🟠 Élevé",IF(G12>=4,"🟡 Modéré","🟢 Faible")))) | L12: =IF(AND(J12<>"",K12<>""),J12*K12,"") | M12: =IF(L12="","",IF(L12>=12,"🔴 Critique",IF(L12>=8,"🟠 Élevé",IF(L12>=4,"🟡 Modéré","🟢 Faible"))))
G13: =IF(AND(E13<>"",F13<>""),E13*F13,"") | H13: =IF(G13="","",IF(G13>=12,"🔴 Critique",IF(G13>=8,"🟠 Élevé",IF(G13>=4,"🟡 Modéré","🟢 Faible")))) | L13: =IF(AND(J13<>"",K13<>""),J13*K13,"") | M13: =IF(L13="","",IF(L13>=12,"🔴 Critique",IF(L13>=8,"🟠 Élevé",IF(L13>=4,"🟡 Modéré","🟢 Faible"))))
G14: =IF(AND(E14<>"",F14<>""),E14*F14,"") | H14: =IF(G14="","",IF(G14>=12,"🔴 Critique",IF(G14>=8,"🟠 Élevé",IF(G14>=4,"🟡 Modéré","🟢 Faible")))) | L14: =IF(AND(J14<>"",K14<>""),J14*K14,"") | M14: =IF(L14="","",IF(L14>=12,"🔴 Critique",IF(L14>=8,"🟠 Élevé",IF(L14>=4,"🟡 Modéré","🟢 Faible"))))

Sheet 9. Dashboard consolidé
A1: DASHBOARD : CARTOGRAPHIE DES RISQUES DE CORRUPTION
A2: 📊 Les scénarios se positionnent automatiquement dans la matrice en fonction des scores saisis dans les onglets 2 à 8.
A4: 🔴 MATRICE DES RISQUES BRUTS (avant mesures de maîtrise) | G4: 🟢 MATRICE DES RISQUES NETS (après mesures de maîtrise)
A6: Probabilité \ Impact | B6: 1. Mineur | C6: 2. Modéré | D6: 3. Majeur | E6: 4. Critique | G6: Probabilité \ Impact | H6: 1. Mineur | I6: 2. Modéré | J6: 3. Majeur | K6: 4. Critique
A7: 4. Très fréquent | B7: =IF(_calc!F113<>"",_calc!F113,"") | C7: =IF(_calc!G113<>"",_calc!G113,"") | D7: =IF(_calc!H113<>"",_calc!H113,"") | E7: =IF(_calc!I113<>"",_calc!I113,"") | G7: 4. Très fréquent | H7: =IF(_calc!V113<>"",_calc!V113,"") | I7: =IF(_calc!W113<>"",_calc!W113,"") | J7: =IF(_calc!X113<>"",_calc!X113,"") | K7: =IF(_calc!Y113<>"",_calc!Y113,"")
A8: 3. Fréquent | B8: =IF(_calc!J113<>"",_calc!J113,"") | C8: =IF(_calc!K113<>"",_calc!K113,"") | D8: =IF(_calc!L113<>"",_calc!L113,"") | E8: =IF(_calc!M113<>"",_calc!M113,"") | G8: 3. Fréquent | H8: =IF(_calc!Z113<>"",_calc!Z113,"") | I8: =IF(_calc!AA113<>"",_calc!AA113,"") | J8: =IF(_calc!AB113<>"",_calc!AB113,"") | K8: =IF(_calc!AC113<>"",_calc!AC113,"")
A9: 2. Peu fréquent | B9: =IF(_calc!N113<>"",_calc!N113,"") | C9: =IF(_calc!O113<>"",_calc!O113,"") | D9: =IF(_calc!P113<>"",_calc!P113,"") | E9: =IF(_calc!Q113<>"",_calc!Q113,"") | G9: 2. Peu fréquent | H9: =IF(_calc!AD113<>"",_calc!AD113,"") | I9: =IF(_calc!AE113<>"",_calc!AE113,"") | J9: =IF(_calc!AF113<>"",_calc!AF113,"") | K9: =IF(_calc!AG113<>"",_calc!AG113,"")
A10: 1. Rare | B10: =IF(_calc!R113<>"",_calc!R113,"") | C10: =IF(_calc!S113<>"",_calc!S113,"") | D10: =IF(_calc!T113<>"",_calc!T113,"") -> Pot-de-vin fournisseur | E10: =IF(_calc!U113<>"",_calc!U113,"") | G10: 1. Rare | H10: =IF(_calc!AH113<>"",_calc!AH113,"") | I10: =IF(_calc!AI113<>"",_calc!AI113,"") | J10: =IF(_calc!AJ113<>"",_calc!AJ113,"") | K10: =IF(_calc!AK113<>"",_calc!AK113,"")
A12: Impact brut → | G12: Impact net →
A14: LÉGENDE
B15: Critique (12-16) | C15: Traitement immédiat, escalade direction
B16: Élevé (8-9) | C16: Plan d'action prioritaire
B17: Modéré (4-6) | C17: Mesures à renforcer, suivi régulier
B18: Faible (1-3) | C18: Surveillance standard
A21: 📋 SYNTHÈSE PAR PROCESSUS
A23: Processus | B23: Nb scénarios | C23: Score brut moyen | D23: Score brut max | E23: Scénario le plus critique | G23: Score net moyen | H23: Score net max | I23: Risques résiduels ≥ 8 | J23: Tendance | K23: Priorité
A24: Achats & Approvisionnement
A25: Commercial & Ventes
A26: RH & Recrutement
A27: Finance & Comptabilité
A28: M&A, Partenariats & JV
A29: Sponsoring, Mécénat & Dons
A30: Relations agents publics
A32: 📋 COUVERTURE DES 8 PILIERS SAPIN 2
A34: Pilier Sapin 2 | B34: Description | C34: Scénarios couverts | D34: Mesures en place | E34: Gaps identifiés | G34: Statut
A35: P1 | B35: Code de conduite
A36: P2 | B36: Dispositif d'alerte interne
A37: P3 | B37: Cartographie des risques
A38: P4 | B38: Évaluation des tiers
A39: P5 | B39: Contrôles comptables
A40: P6 | B40: Formation
A41: P7 | B41: Régime disciplinaire
A42: P8 | B42: Contrôle et évaluation interne

Sheet 10. Plan de remédiation
A1: PLAN DE REMÉDIATION : SUIVI DES ACTIONS
A2: ✅ Listez ici les actions correctives pour tous les risques résiduels ≥ 8 (Élevé ou Critique)
A4: N° | B4: Scénario concerné | C4: Processus | D4: Score résiduel | E4: Action corrective | F4: Pilote | G4: Échéance | H4: Statut | I4: Avancement | J4: Commentaires

Sheet 11. Historique révisions
A1: HISTORIQUE DES RÉVISIONS DE LA CARTOGRAPHIE
A3: Version | B3: Date | C3: Révisé par | D3: Validé par | E3: Nature des modifications | F3: Commentaires

Sheet 12. Indicateurs
A1: INDICATEURS COMPLÉMENTAIRES : SIGNAUX D'ALERTE CORRUPTION & FRAUDE
A2: Ces indicateurs constituent des signaux d'alerte transversaux à croiser avec les scénarios de corruption. Ils proviennent de l'analyse des données comptables, juridiques et opérationnelles.
A4: Indicateur d'alerte | B4: Classification | C4: Catégorie | D4: Scénarios associés
A5: Capitaux propres négatifs sur une longue période | B5: Corruption / Fraude | C5: Incohérence comptable | D5: A2, A5, F2, F4
A6: Sous-traitance élevée rapportée au CA | B6: Corruption | C6: Incohérence comptable | D6: A1, A2, C2
A7: Masse salariale trop faible | B7: Fraude | C7: Incohérence comptable | D7: R2, F4
A8: Présentation de comptes annuels non réguliers | B8: Corruption / Fraude | C8: Incohérence comptable | D8: F2, F5
A9: Changements fréquents de dirigeants | B9: Corruption | C9: Administration société | D9: M1, M3
A10: Changements fréquents de bénéficiaires effectifs | B10: Corruption | C10: Administration société | D10: A5, F4, M1
A11: Mandataires ayant liquidé plusieurs sociétés | B11: Fraude | C11: Administration société | D11: A5, F4
A12: Société en redressement judiciaire | B12: Corruption / Fraude | C12: Administration société | D12: A1, C5
A13: Le tiers est une société écran | B13: Corruption | C13: Administration société | D13: A5, F4, S1
A14: Adresse atypique du siège social | B14: Fraude | C14: Administration société | D14: A5, F4
A15: Données bancaires communes à plusieurs entités | B15: Corruption / Fraude | C15: Banque | D15: A5, F4, F5
... A26: Paiements vers des pays tiers sans lien opérationnel | B26: Corruption | C26: Flux financiers | D26: F1, F5, C2

Sheet 13. Scénarios corruption
A1: FICHES SCÉNARIOS DE CORRUPTION
A2: Détaillez ici les scénarios les plus critiques avec le mécanisme de corruption, les signaux d'alerte et un cas réel (AFA, PNF, CJIP) pour former les équipes.
A4: N° | B4: Scénario | C4: Mécanisme de corruption | D4: Red flags / signaux d'alerte | E4: Cas réel de référence | F4: Processus concerné
A5: 1 | B5: Surfacturation complice (Achats) | C5: Un fournisseur facture un montant supérieur à la prestation réelle. Un collaborateur interne valide la facture en connaissance de cause. L'écart entre le prix réel et le prix facturé est partagé entre le fournisseur et le collaborateur. | D5: • Écart significatif entre devis et facture • Pas de bon de commande préalable • Prestation intellectuelle sans livrable vérifiable • Même fournisseur systématiquement retenu | E5: [À compléter : cas AFA/PNF/CJIP] | F5: Achats
A6: 2 | B6: Commission occulte à intermédiaire (Commercial) | C6: L'entreprise mandate un agent commercial pour décrocher un contrat à l'international. L'agent reverse une partie de sa commission au décideur chez le client. L'entreprise est exposée même si elle n'a pas directement versé le pot-de-vin. | D6: • Commission > 10-15% du montant du contrat • Agent sans structure visible • Agent imposé par le client • Pas de contrat de prestation formalisé | E6: [À compléter : cas AFA/PNF/CJIP] | F6: Commercial
A7: 3 | B7: Don comme véhicule de corruption (Sponsoring) | C7: L'entreprise finance une association dirigée par un élu local. En contrepartie, l'élu facilite l'obtention d'un permis de construire ou d'une autorisation administrative pour un projet de l'entreprise. | D7: • Association récemment créée • Dirigeant = décideur public en lien avec l'entreprise • Pas de suivi de l'utilisation des fonds • Montant disproportionné | E7: [À compléter : cas AFA/PNF/CJIP] | F7: Sponsoring

Sheet _calc
A2: =IF('2. Achats'!B5<>"",'2. Achats'!B5,"") -> Pot-de-vin fournisseur | B2: =IF('2. Achats'!E5<>"",'2. Achats'!E5,"") -> 1 | C2: =IF('2. Achats'!F5<>"",'2. Achats'!F5,"") -> 3 | D2: =IF('2. Achats'!J5<>"",'2. Achats'!J5,"") | E2: =IF('2. Achats'!K5<>"",'2. Achats'!K5,"") | F2: =IF(AND(B2=4,C2=1),A2,"") | G2: =IF(AND(B2=4,C2=2),A2,"") | H2: =IF(AND(B2=4,C2=3),A2,"") | I2: =IF(AND(B2=4,C2=4),A2,"") | J2: =IF(AND(B2=3,C2=1),A2,"") | K2: =IF(AND(B2=3,C2=2),A2,"") | L2: =IF(AND(B2=3,C2=3),A2,"") | M2: =IF(AND(B2=3,C2=4),A2,"") | N2: =IF(AND(B2=2,C2=1),A2,"") | O2: =IF(AND(B2=2,C2=2),A2,"") | P2: =IF(AND(B2=2,C2=3),A2,"") | Q2: =IF(AND(B2=2,C2=4),A2,"") | R2: =IF(AND(B2=1,C2=1),A2,"") | S2: =IF(AND(B2=1,C2=2),A2,"") | T2: =IF(AND(B2=1,C2=3),A2,"") -> Pot-de-vin fournisseur | U2: =IF(AND(B2=1,C2=4),A2,"") | V2: =IF(AND(D2=4,E2=1),A2,"") | W2: =IF(AND(D2=4,E2=2),A2,"") | X2: =IF(AND(D2=4,E2=3),A2,"") | Y2: =IF(AND(D2=4,E2=4),A2,"") | Z2: =IF(AND(D2=3,E2=1),A2,"") | AA2: =IF(AND(D2=3,E2=2),A2,"") | AB2: =IF(AND(D2=3,E2=3),A2,"") | AC2: =IF(AND(D2=3,E2=4),A2,"") | AD2: =IF(AND(D2=2,E2=1),A2,"") | AE2: =IF(AND(D2=2,E2=2),A2,"") | AF2: =IF(AND(D2=2,E2=3),A2,"") | AG2: =IF(AND(D2=2,E2=4),A2,"") | AH2: =IF(AND(D2=1,E2=1),A2,"") | AI2: =IF(AND(D2=1,E2=2),A2,"") | AJ2: =IF(AND(D2=1,E2=3),A2,"") | AK2: =IF(AND(D2=1,E2=4),A2,"")
A3: =IF('2. Achats'!B6<>"",'2. Achats'!B6,"") -> Surfacturation complice | B3: =IF('2. Achats'!E6<>"",'2. Achats'!E6,"") | C3: =IF('2. Achats'!F6<>"",'2. Achats'!F6,"") | D3: =IF('2. Achats'!J6<>"",'2. Achats'!J6,"") | E3: =IF('2. Achats'!K6<>"",'2. Achats'!K6,"") | F3: =IF(AND(B3=4,C3=1),IF(F2<>"",F2&CHAR(10)&A3,A3),F2) | G3: =IF(AND(B3=4,C3=2),IF(G2<>"",G2&CHAR(10)&A3,A3),G2) | H3: =IF(AND(B3=4,C3=3),IF(H2<>"",H2&CHAR(10)&A3,A3),H2) | I3: =IF(AND(B3=4,C3=4),IF(I2<>"",I2&CHAR(10)&A3,A3),I2) | J3: =IF(AND(B3=3,C3=1),IF(J2<>"",J2&CHAR(10)&A3,A3),J2) | K3: =IF(AND(B3=3,C3=2),IF(K2<>"",K2&CHAR(10)&A3,A3),K2) | L3: =IF(AND(B3=3,C3=3),IF(L2<>"",L2&CHAR(10)&A3,A3),L2) | M3: =IF(AND(B3=3,C3=4),IF(M2<>"",M2&CHAR(10)&A3,A3),M2) | N3: =IF(AND(B3=2,C3=1),IF(N2<>"",N2&CHAR(10)&A3,A3),N2) | O3: =IF(AND(B3=2,C3=2),IF(O2<>"",O2&CHAR(10)&A3,A3),O2) | P3: =IF(AND(B3=2,C3=3),IF(P2<>"",P2&CHAR(10)&A3,A3),P2) | Q3: =IF(AND(B3=2,C3=4),IF(Q2<>"",Q2&CHAR(10)&A3,A3),Q2) | R3: =IF(AND(B3=1,C3=1),IF(R2<>"",R2&CHAR(10)&A3,A3),R2) | S3: =IF(AND(B3=1,C3=2),IF(S2<>"",S2&CHAR(10)&A3,A3),S2) | T3: =IF(AND(B3=1,C3=3),IF(T2<>"",T2&CHAR(10)&A3,A3),T2) -> Pot-de-vin fournisseur | U3: =IF(AND(B3=1,C3=4),IF(U2<>"",U2&CHAR(10)&A3,A3),U2) | V3: =IF(AND(D3=4,E3=1),IF(V2<>"",V2&CHAR(10)&A3,A3),V2) | W3: =IF(AND(D3=4,E3=2),IF(W2<>"",W2&CHAR(10)&A3,A3),W2) | X3: =IF(AND(D3=4,E3=3),IF(X2<>"",X2&CHAR(10)&A3,A3),X2) | Y3: =IF(AND(D3=4,E3=4),IF(Y2<>"",Y2&CHAR(10)&A3,A3),Y2) | Z3: =IF(AND(D3=3,E3=1),IF(Z2<>"",Z2&CHAR(10)&A3,A3),Z2) | AA3: =IF(AND(D3=3,E3=2),IF(AA2<>"",AA2&CHAR(10)&A3,A3),AA2) | AB3: =IF(AND(D3=3,E3=3),IF(AB2<>"",AB2&CHAR(10)&A3,A3),AB2) | AC3: =IF(AND(D3=3,E3=4),IF(AC2<>"",AC2&CHAR(10)&A3,A3),AC2) | AD3: =IF(AND(D3=2,E3=1),IF(AD2<>"",AD2&CHAR(10)&A3,A3),AD2) | AE3: =IF(AND(D3=2,E3=2),IF(AE2<>"",AE2&CHAR(10)&A3,A3),AE2) | AF3: =IF(AND(D3=2,E3=3),IF(AF2<>"",AF2&CHAR(10)&A3,A3),AF2) | AG3: =IF(AND(D3=2,E3=4),IF(AG2<>"",AG2&CHAR(10)&A3,A3),AG2) | AH3: =IF(AND(D3=1,E3=1),IF(AH2<>"",AH2&CHAR(10)&A3,A3),AH2) | AI3: =IF(AND(D3=1,E3=2),IF(AI2<>"",AI2&CHAR(10)&A3,A3),AI2) | AJ3: =IF(AND(D3=1,E3=3),IF(AJ2<>"",AJ2&CHAR(10)&A3,A3),AJ2) | AK3: =IF(AND(D3=1,E3=4),IF(AK2<>"",AK2&CHAR(10)&A3,A3),AK2)
A4: =IF('2. Achats'!B7<>"",'2. Achats'!B7,"") -> Fractionnement de commandes | B4: =IF('2. Achats'!E7<>"",'2. Achats'!E7,"") | C4: =IF('2. Achats'!F7<>"",'2. Achats'!F7,"") | D4: =IF('2. Achats'!J7<>"",'2. Achats'!J7,"") | E4: =IF('2. Achats'!K7<>"",'2. Achats'!K7,"") | F4: =IF(AND(B4=4,C4=1),IF(F3<>"",F3&CHAR(10)&A4,A4),F3) | G4: =IF(AND(B4=4,C4=2),IF(G3<>"",G3&CHAR(10)&A4,A4),G3) | H4: =IF(AND(B4=4,C4=3),IF(H3<>"",H3&CHAR(10)&A4,A4),H3) | I4: =IF(AND(B4=4,C4=4),IF(I3<>"",I3&CHAR(10)&A4,A4),I3) | J4: =IF(AND(B4=3,C4=1),IF(J3<>"",J3&CHAR(10)&A4,A4),J3) | K4: =IF(AND(B4=3,C4=2),IF(K3<>"",K3&CHAR(10)&A4,A4),K3) | L4: =IF(AND(B4=3,C4=3),IF(L3<>"",L3&CHAR(10)&A4,A4),L3) | M4: =IF(AND(B4=3,C4=4),IF(M3<>"",M3&CHAR(10)&A4,A4),M3) | N4: =IF(AND(B4=2,C4=1),IF(N3<>"",N3&CHAR(10)&A4,A4),N3) | O4: =IF(AND(B4=2,C4=2),IF(O3<>"",O3&CHAR(10)&A4,A4),O3) | P4: =IF(AND(B4=2,C4=3),IF(P3<>"",P3&CHAR(10)&A4,A4),P3) | Q4: =IF(AND(B4=2,C4=4),IF(Q3<>"",Q3&CHAR(10)&A4,A4),Q3) | R4: =IF(AND(B4=1,C4=1),IF(R3<>"",R3&CHAR(10)&A4,A4),R3) | S4: =IF(AND(B4=1,C4=2),IF(S3<>"",S3&CHAR(10)&A4,A4),S3) | T4: =IF(AND(B4=1,C4=3),IF(T3<>"",T3&CHAR(10)&A4,A4),T3) -> Pot-de-vin fournisseur | U4: =IF(AND(B4=1,C4=4),IF(U3<>"",U3&CHAR(10)&A4,A4),U3) | V4: =IF(AND(D4=4,E4=1),IF(V3<>"",V3&CHAR(10)&A4,A4),V3) | W4: =IF(AND(D4=4,E4=2),IF(W3<>"",W3&CHAR(10)&A4,A4),W3) | X4: =IF(AND(D4=4,E4=3),IF(X3<>"",X3&CHAR(10)&A4,A4),X3) | Y4: =IF(AND(D4=4,E4=4),IF(Y3<>"",Y3&CHAR(10)&A4,A4),Y3) | Z4: =IF(AND(D4=3,E4=1),IF(Z3<>"",Z3&CHAR(10)&A4,A4),Z3) | AA4: =IF(AND(D4=3,E4=2),IF(AA3<>"",AA3&CHAR(10)&A4,A4),AA3) | AB4: =IF(AND(D4=3,E4=3),IF(AB3<>"",AB3&CHAR(10)&A4,A4),AB3) | AC4: =IF(AND(D4=3,E4=4),IF(AC3<>"",AC3&CHAR(10)&A4,A4),AC3) | AD4: =IF(AND(D4=2,E4=1),IF(AD3<>"",AD3&CHAR(10)&A4,A4),AD3) | AE4: =IF(AND(D4=2,E4=2),IF(AE3<>"",AE3&CHAR(10)&A4,A4),AE3) | AF4: =IF(AND(D4=2,E4=3),IF(AF3<>"",AF3&CHAR(10)&A4,A4),AF3) | AG4: =IF(AND(D4=2,E4=4),IF(AG3<>"",AG3&CHAR(10)&A4,A4),AG3) | AH4: =IF(AND(D4=1,E4=1),IF(AH3<>"",AH3&CHAR(10)&A4,A4),AH3) | AI4: =IF(AND(D4=1,E4=2),IF(AI3<>"",AI3&CHAR(10)&A4,A4),AI3) | AJ4: =IF(AND(D4=1,E4=3),IF(AJ3<>"",AJ3&CHAR(10)&A4,A4),AJ3) | AK4: =IF(AND(D4=1,E4=4),IF(AK3<>"",AK3&CHAR(10)&A4,A4),AK3)
